# examples/pex: Fix Python 3.11 support

**gcagle3** commented *May 17, 2023*

The `pex` example was recently updated to support Python 3.8-3.11. We are opening this issue to report a bug in Python 3.11 support due to the 'rU' mode being removed. Current error when running the `pex` example using Python 3.11:

```
│ The data source received an unexpected error while attempting to execute the program.
│ 
│ Program: python3
│ Error Message: Traceback (most recent call last):
│   File "/terraform-aws-utilities/examples/pex/sample-python-script/bin/sample_python_script_py3_env.pex/.bootstrap/pex/pex.py", line 349, in execute
│   File "/terraform-aws-utilities/examples/pex/sample-python-script/bin/sample_python_script_py3_env.pex/.bootstrap/pex/pex.py", line 276, in patch_sys
│   File "/terraform-aws-utilities/examples/pex/sample-python-script/bin/sample_python_script_py3_env.pex/.bootstrap/pex/pex.py", line 244, in minimum_sys
│   File "/terraform-aws-utilities/examples/pex/sample-python-script/bin/sample_python_script_py3_env.pex/.bootstrap/pex/pex.py", line 119, in _extras_paths
│   File "/terraform-aws-utilities/examples/pex/sample-python-script/bin/sample_python_script_py3_env.pex/.bootstrap/pex/util.py", line 228, in iter_pth_paths
    asample-python-script",
│ ValueError: invalid mode: 'rU'
│ Traceback (most recent call last):
│   File "<string>", line 6, in <module>
│   File "~/.pyenv/versions/3.11.0/lib/python3.11/subprocess.py"r line 413, in check_call
│     raise CalledProcessError(retcode, cmd)
│ subprocess.CalledProcessError: Command '['python3', './sample-python-script/bin/sample_python_script_py3_env.pex', '../../modules/prepare-pex-environment/entrypoint.py', 'sample_python_script.main:main',
│ '--is-data']' returned non-zero exit status 1.
│ 
│ State: exit status 1
```

PEX binary will need to be updated to correctly support Python 3.11.
<br />
***


